{"uuid": "8c954ba3-841a-4964-8898-cf5456473b28", "children": ["29911c8e-3702-450b-a36d-5e992fc2ad3e"], "befores": [{"name": "app_page", "status": "broken", "statusDetails": {"message": "selenium.common.exceptions.WebDriverException: Message: An unknown server-side error occurred while processing the command. Original error: Error getting default IME. Original error: Error executing adbExec. Original error: 'Command 'D:\\\\Users\\\\laixinhua\\\\AppData\\\\Local\\\\Android\\\\android-sdk\\\\platform-tools\\\\adb.exe -P 5037 -s emulator-5554 shell settings get secure default_input_method' timed out after 20000ms'. Try to increase the 20000ms adb execution timeout represented by 'adbExecTimeout' capability\nStacktrace:\nUnknownError: An unknown server-side error occurred while processing the command. Original error: Error getting default IME. Original error: Error executing adbExec. Original error: 'Command 'D:\\\\Users\\\\laixinhua\\\\AppData\\\\Local\\\\Android\\\\android-sdk\\\\platform-tools\\\\adb.exe -P 5037 -s emulator-5554 shell settings get secure default_input_method' timed out after 20000ms'. Try to increase the 20000ms adb execution timeout represented by 'adbExecTimeout' capability\n    at getResponseForW3CError (C:\\Users\\laixinhua\\AppData\\Local\\Programs\\Appium Server GUI\\resources\\app\\node_modules\\appium\\node_modules\\appium-base-driver\\lib\\protocol\\errors.js:804:9)\n    at asyncHandler (C:\\Users\\laixinhua\\AppData\\Local\\Programs\\Appium Server GUI\\resources\\app\\node_modules\\appium\\node_modules\\appium-base-driver\\lib\\protocol\\protocol.js:380:37)\n", "trace": "  File \"E:\\Users\\laixinhua\\PycharmProjects\\LittleBearAutoTest\\venv\\lib\\site-packages\\pluggy\\_callers.py\", line 39, in _multicall\n    res = hook_impl.function(*args)\n  File \"E:\\Users\\laixinhua\\PycharmProjects\\LittleBearAutoTest\\venv\\lib\\site-packages\\_pytest\\fixtures.py\", line 1111, in pytest_fixture_setup\n    result = call_fixture_func(fixturefunc, request, kwargs)\n  File \"E:\\Users\\laixinhua\\PycharmProjects\\LittleBearAutoTest\\venv\\lib\\site-packages\\_pytest\\fixtures.py\", line 883, in call_fixture_func\n    fixture_result = next(generator)\n  File \"E:\\Users\\laixinhua\\PycharmProjects\\LittleBearAutoTest\\conftest.py\", line 28, in app_page\n    driver = webdriver.Remote('http://' + str(data['desired_caps']['ip']) + ':' + str(data['desired_caps']['port']) + '/wd/hub',data['desired_caps'])\n  File \"E:\\Users\\laixinhua\\PycharmProjects\\LittleBearAutoTest\\venv\\lib\\site-packages\\appium\\webdriver\\webdriver.py\", line 274, in __init__\n    super().__init__(\n  File \"E:\\Users\\laixinhua\\PycharmProjects\\LittleBearAutoTest\\venv\\lib\\site-packages\\selenium\\webdriver\\remote\\webdriver.py\", line 269, in __init__\n    self.start_session(capabilities, browser_profile)\n  File \"E:\\Users\\laixinhua\\PycharmProjects\\LittleBearAutoTest\\venv\\lib\\site-packages\\appium\\webdriver\\webdriver.py\", line 369, in start_session\n    response = self.execute(RemoteCommand.NEW_SESSION, parameters)\n  File \"E:\\Users\\laixinhua\\PycharmProjects\\LittleBearAutoTest\\venv\\lib\\site-packages\\selenium\\webdriver\\remote\\webdriver.py\", line 425, in execute\n    self.error_handler.check_response(response)\n  File \"E:\\Users\\laixinhua\\PycharmProjects\\LittleBearAutoTest\\venv\\lib\\site-packages\\selenium\\webdriver\\remote\\errorhandler.py\", line 247, in check_response\n    raise exception_class(message, screen, stacktrace)\n"}, "start": 1663752998981, "stop": 1663753038601}], "start": 1663752998981, "stop": 1663753038655}